Workbook

Sheet 0. Resumo
A1: PROJECTO ECHO ANGOLA — LITERACIA EM IA PARA O DESENVOLVIMENTO NACIONAL
A2: ORÇAMENTO — RESUMO EXECUTIVO | 500 000 USD | 12 meses | Set 2026 – Ago 2027
A4: Entidade Proponente | C4: CEPCEP / Universidade Católica Portuguesa
A5: País / Região | C5: Angola — Luanda (5 000 beneficiários directos)
A6: Entidade Financiadora | C6: UE / PNUD / Camões I.P.
A7: Duração | C7: 12 meses — Set 2026 a Ago 2027
A8: Objectivo Geral | C8: Reforçar a literacia digital e em IA de 5 000 cidadãos angolanos via formação modular certificada
A10: RUBRICA PRAG | B10: USD | C10: % Total | D10: Descrição Sumária
A11: 1. Recursos Humanos | B11: ='2. Orçamento PRAG'!H27 -> 200000 | C11: =B11/B22 -> 0.4 | D11: Equipa local Luanda (Coord.+1 Esp.Ped.+1 TIC+6 Assist.+Admin+Log.) + back office UCP Lisboa + per diems
A12: 2. Viagens | B12: ='2. Orçamento PRAG'!H31 -> 20000 | C12: =B12/B22 -> 0.04 | D12: 4 missões internacionais PT–Angola (A/R) + transportes locais em Luanda
A13: 3. Equipamento e Materiais | B13: ='2. Orçamento PRAG'!H37 -> 75000 | C13: =B13/B22 -> 0.15 | D13: 60 tablets + 2 servidores locais + material pedagógico + kits de formação
A14: 4. Escritório do Projecto | B14: ='2. Orçamento PRAG'!H43 -> 12000 | C14: =B14/B22 -> 0.024 | D14: Luanda: arrendamento, veículo, comunicações, consumíveis (12 meses)
A15: 5. Outras Despesas e Serviços | B15: ='2. Orçamento PRAG'!H53 -> 99000 | C15: =B15/B22 -> 0.198 | D15: 50 ciclos de formação (300 sessões-módulo), auditoria, avaliação externa, tradução, comunicação, certificados
A16: 6. Outros Custos Directos | B16: ='2. Orçamento PRAG'!H57 -> 43000 | C16: =B16/B22 -> 0.086 | D16: Plataforma digital offline (desenvolvimento) + certificação oficial MINTTICS/MED
A17: 7.1 Subtotal Diretos (excl. Escritório) | B17: ='2. Orçamento PRAG'!H59 -> 437000 | C17: =B17/B22 -> 0.874
A18: 7.2 Subtotal Diretos Elegíveis (1–6) | B18: ='2. Orçamento PRAG'!H60 -> 449000 | C18: =B18/B22 -> 0.898
A19: 8. Custos Indiretos (7% × 7.1) | B19: ='2. Orçamento PRAG'!H61 -> 30590 | C19: =B19/B22 -> 0.06118
A20: 9. Total Custos Elegíveis (7.2 + 8) | B20: ='2. Orçamento PRAG'!H62 -> 479590 | C20: =B20/B22 -> 0.95918
A21: 10.1 Reserva para Imprevistos (≤ 5% de 7.2) | B21: ='2. Orçamento PRAG'!H63 -> 20410 | C21: =B21/B22 -> 0.04082
A22: 11. TOTAL DOS CUSTOS ELEGÍVEIS DA ACÇÃO | B22: ='2. Orçamento PRAG'!H64 -> 500000 | C22: =B22/B22 -> 1
A24: FONTES DE FINANCIAMENTO PREVISTAS
A25: A. Contribuição UE/PNUD (solicitada) | B25: 400000 | C25: 0.8 | D25: 80% dos custos elegíveis totais
A26: B. Cofinanciamento (UCP/CEPCEP + parceiros locais) | B26: 100000 | C26: 0.2 | D26: UCP 10% (fundos próprios) + parceiros locais 10%
A27: TOTAL CONTRIBUIÇÕES (A + B) | B27: 500000 | C27: 1 | D27: Equilibrado com total de custos elegíveis

Sheet 1. RH por Pessoa
A1: PROJECTO ECHO ANGOLA — RECURSOS HUMANOS: DESDOBRAMENTO POR PESSOA
A2: Entidade: CEPCEP/UCP • Angola — Luanda • 12 meses (Set 2026–Ago 2027) • Moeda: USD
A4: Cód. | B4: Função / Cargo | C4: Tipo | D4: Local | E4: Venc.Bruto Mensal (USD) | F4: % Afet. | G4: Meses | H4: Custo Total (USD) | I4: Actividades Principais
A5: A. PESSOAL TÉCNICO LOCAL — Rubrica 1.1.1
A6: RH-01 | B6: Coordenador(a) Operacional de Terreno | C6: Local | D6: Luanda | E6: 1800 | F6: 1 | G6: 12 | H6: =E6*F6*G6*1 -> 21600 | I6: Coord. geral no terreno; liaisons MINTTICS/MED/FAS/UAN; relatórios mensais (A.1, A.6, A.7)
A7: RH-02 | B7: Especialista Pedagógico(a) — Luanda | C7: Local | D7: Luanda | E7: 1500 | F7: 1 | G7: 12 | H7: =E7*F7*G7*1 -> 18000 | I7: Desenvolvimento curricular; supervisão pedagógica; ToT Luanda (A.2, A.3, A.5)
A8: RH-03 | B8: Técnico(a) TIC — Luanda | C8: Local | D8: Luanda | E8: 1200 | F8: 1 | G8: 12 | H8: =E8*F8*G8*1 -> 14400 | I8: Plataforma offline Luanda; manutenção tablets; formação técnica facilitadores (A.4)
A9: RH-04 | B9: Assistente de Campo (×6 colaboradores) | C9: Local | D9: Luanda | E9: 900 | F9: 1 | G9: 12 | H9: =E9*F9*G9*6 -> 64800 | I9: Mobilização comunitária; registo participantes; logística dos 50 ciclos de formação; recolha dados M&A (A.5)
A10: SUBTOTAL A — Pessoal Técnico Local (1.1.1) | H10: =H6+H7+H8+H9 -> 118800
A11: B. PESSOAL ADMINISTRATIVO E DE APOIO — Rubrica 1.1.2
A12: RH-05 | B12: Assistente Administrativo(a)-Financeiro(a) | C12: Local | D12: Luanda | E12: 1000 | F12: 1 | G12: 12 | H12: =E12*F12*G12*1 -> 12000 | I12: Gestão financeira diária; prestação de contas; compras e contratos locais
A13: RH-06 | B13: Logístico(a) / Motorista | C13: Local | D13: Luanda | E13: 800 | F13: 1 | G13: 12 | H13: =E13*F13*G13*1 -> 9600 | I13: Transporte equipa em Luanda; gestão armazém; apoio logístico aos 50 ciclos
A14: SUBTOTAL B — Pessoal Administrativo e Apoio (1.1.2) | H14: =H12+H13 -> 21600
A15: C. PESSOAL INTERNACIONAL / BACK OFFICE (Sede UCP Lisboa) — Rubrica 1.2
A16: RH-07 | B16: Diretor(a) Técnico(a) do Projecto — UCP (30% ETI) | C16: Intern. | D16: Lisboa | E16: 1500 | F16: 1 | G16: 12 | H16: =E16*F16*G16*1 -> 18000 | I16: Dir. técnica (0.30 × 5 000 USD/mês); validação curricular; rel. doadores; supervisão (A.1)
A17: RH-08 | B17: Gestora Financeira — UCP (20% ETI) | C17: Intern. | D17: Lisboa | E17: 900 | F17: 1 | G17: 12 | H17: =E17*F17*G17*1 -> 10800 | I17: Gestão financeira global (0.20 × 4 500 USD/mês); relatórios financeiros; auditoria interna
A18: RH-09 | B18: Assessor(a) M&A e Avaliação — UCP (15% ETI) | C18: Intern. | D18: Lisboa | E18: 600 | F18: 1 | G18: 12 | H18: =E18*F18*G18*1 -> 7200 | I18: M&A (0.15 × 4 000 USD/mês); avaliações intercalares e finais; análise de impacto (A.6)
A19: SUBTOTAL C — Pessoal Internacional / Back Office (1.2) | H19: =H16+H17+H18 -> 36000
A20: TOTAL SALÁRIOS (Rubricas 1.1 + 1.2) | H20: =H10+H14+H19 -> 176400
A22: 1.3 AJUDAS DE CUSTO PARA DESLOCAÇÕES EM SERVIÇO (Rubrica 1.3)
A23: Rubrica | B23: Descrição | C23: Unidade | D23: Qtd. | E23: Val.Unit.(USD) | F23: Total (USD) | G23: Notas (cols 7–12)
A24: 1.3.1 | B24: Ajudas de custo — missões internacionais (pessoal sede Lisboa) | C24: Por dia | D24: 24 | E24: 150 | F24: =D24*E24 -> 3600 | G24: 4 missões × 6 dias/missão — equipa UCP Lisboa
A25: 1.3.2 | B25: Ajudas de custo — deslocações locais em Luanda (pessoal terreno) | C25: Por dia | D25: 340 | E25: 40 | F25: =D25*E25 -> 13600 | G25: ~28 dias/mês × 12 meses — deslocações intra-cidade da equipa de terreno
A26: 1.3.3 | B26: Ajudas de custo — participantes ToT e seminários | C26: Por dia | D26: 640 | E26: 10 | F26: =D26*E26 -> 6400 | G26: 60 facilitadores × 10d ToT + workshops e eventos
A27: SUBTOTAL 1.3 — Ajudas de Custo | F27: =F24+F25+F26 -> 23600 | G27: Subtotal 1.3.1+1.3.2+1.3.3
A28: TOTAL RUBRICA 1 — RECURSOS HUMANOS (Salários + Ajudas de Custo) | F28: =H20+F27 -> 200000 | G28: Total: 200 000 USD — coincide com a Rubrica 1 do Orçamento PRAG

Sheet 2. Orçamento PRAG
A1: PROJECTO ECHO ANGOLA — ORÇAMENTO DA ACÇÃO (Estrutura PRAG / Anexo B)
A2: CEPCEP/UCP • Angola (Luanda) • 12 meses (Set 2026–Ago 2027) • Moeda: USD — Azul: inputs; Preto: fórmulas
A4: RUBRICA ORÇAMENTAL | B4: Unidade | C4: Valor Unit. (USD) | D4: Qtd. M1–M6 | E4: Qtd. M7–M12 | F4: Custo M1–M6 | G4: Custo M7–M12 | H4: Custo Total (USD) | I4: Notas / Pressupostos
A5: 1. RECURSOS HUMANOS
A6: 1.1 Salários brutos (pessoal local)
A7: 1.1.1 Pessoal técnico local
A8: Coordenador(a) Operacional (RH-01) | B8: Por mês | C8: 1800 | D8: 6 | E8: 6 | F8: =C8*D8 -> 10800 | G8: =C8*E8 -> 10800 | H8: =F8+G8 -> 21600 | I8: 12m × 1 800 USD — coord. geral; liaisons MINTTICS/MED/FAS/UAN
A9: Especialista Pedagógico(a) — Luanda (RH-02) | B9: Por mês | C9: 1500 | D9: 6 | E9: 6 | F9: =C9*D9 -> 9000 | G9: =C9*E9 -> 9000 | H9: =F9+G9 -> 18000 | I9: 12m × 1 500 USD — currículo; supervisão pedagógica Luanda
A10: Técnico(a) TIC — Luanda (RH-03) | B10: Por mês | C10: 1200 | D10: 6 | E10: 6 | F10: =C10*D10 -> 7200 | G10: =C10*E10 -> 7200 | H10: =F10+G10 -> 14400 | I10: 12m × 1 200 USD — plataforma offline; suporte técnico Luanda
A11: Assistentes de Campo (×6) (RH-04) | B11: Por p./mês | C11: 900 | D11: 36 | E11: 36 | F11: =C11*D11 -> 32400 | G11: =C11*E11 -> 32400 | H11: =F11+G11 -> 64800 | I11: 6 pessoas × 12 meses × 900 USD — mobilização comunitária; logística dos ciclos; M&A
A12: 1.1.1 Subtotal Pessoal Técnico Local | F12: =F8+F9+F10+F11 -> 59400 | G12: =G8+G9+G10+G11 -> 59400 | H12: =H8+H9+H10+H11 -> 118800
A13: 1.1.2 Pessoal administrativo e de apoio local
A14: Assist. Admin.-Financeiro(a) (RH-05) | B14: Por mês | C14: 1000 | D14: 6 | E14: 6 | F14: =C14*D14 -> 6000 | G14: =C14*E14 -> 6000 | H14: =F14+G14 -> 12000 | I14: 12m × 1 000 USD — gestão financeira; contratos; prestação de contas
A15: Logístico(a) / Motorista (RH-06) | B15: Por mês | C15: 800 | D15: 6 | E15: 6 | F15: =C15*D15 -> 4800 | G15: =C15*E15 -> 4800 | H15: =F15+G15 -> 9600 | I15: 12m × 800 USD — transporte equipa; armazém; apoio logístico aos 50 ciclos de formação
A16: 1.1.2 Subtotal Pessoal Administrativo e Apoio | F16: =F14+F15 -> 10800 | G16: =G14+G15 -> 10800 | H16: =H14+H15 -> 21600
A17: 1.2 Pessoal internacional / back office (sede UCP Lisboa)
A18: Dir. Técnico(a) Projecto — 30% ETI (RH-07) | B18: Por mês | C18: 1500 | D18: 6 | E18: 6 | F18: =C18*D18 -> 9000 | G18: =C18*E18 -> 9000 | H18: =F18+G18 -> 18000 | I18: 0.30×5 000 USD/mês×12m — dir. técnica; rel. doadores; supervisão
A19: Gestora Financeira — 20% ETI (RH-08) | B19: Por mês | C19: 900 | D19: 6 | E19: 6 | F19: =C19*D19 -> 5400 | G19: =C19*E19 -> 5400 | H19: =F19+G19 -> 10800 | I19: 0.20×4 500 USD/mês×12m — relatórios financeiros; auditoria interna
A20: Assessor(a) M&A — 15% ETI (RH-09) | B20: Por mês | C20: 600 | D20: 6 | E20: 6 | F20: =C20*D20 -> 3600 | G20: =C20*E20 -> 3600 | H20: =F20+G20 -> 7200 | I20: 0.15×4 000 USD/mês×12m — M&A; avaliações; análise de impacto
A21: 1.2 Subtotal Pessoal Internacional | F21: =F18+F19+F20 -> 18000 | G21: =G18+G19+G20 -> 18000 | H21: =H18+H19+H20 -> 36000
A22: 1.3 Ajudas de custo para deslocações em serviço
A23: 1.3.1 Missões internacionais (Lisboa–Luanda) | B23: Por dia | C23: 150 | D23: 12 | E23: 12 | F23: =C23*D23 -> 1800 | G23: =C23*E23 -> 1800 | H23: =F23+G23 -> 3600 | I23: 24d × 150 USD — 4 missões × 6 dias — equipa UCP Lisboa
A24: 1.3.2 Deslocações locais em Luanda | B24: Por dia | C24: 40 | D24: 170 | E24: 170 | F24: =C24*D24 -> 6800 | G24: =C24*E24 -> 6800 | H24: =F24+G24 -> 13600 | I24: 340d × 40 USD — equipa de terreno, deslocações intra-cidade (~28 d/mês)
A25: 1.3.3 Participantes ToT e seminários | B25: Por dia | C25: 10 | D25: 320 | E25: 320 | F25: =C25*D25 -> 3200 | G25: =C25*E25 -> 3200 | H25: =F25+G25 -> 6400 | I25: 640d × 10 USD — 60 facilitadores em ToT e workshops
A26: 1.3 Subtotal Ajudas de Custo | F26: =F23+F24+F25 -> 11800 | G26: =G23+G24+G25 -> 11800 | H26: =H23+H24+H25 -> 23600
A27: SUBTOTAL 1. RECURSOS HUMANOS | F27: =F12+F16+F21+F26 -> 100000 | G27: =G12+G16+G21+G26 -> 100000 | H27: =H12+H16+H21+H26 -> 200000
A28: 2. VIAGENS
A29: 2.1 Viagens internacionais (Lisboa–Luanda) | B29: Por voo | C29: 2000 | D29: 2 | E29: 2 | F29: =C29*D29 -> 4000 | G29: =C29*E29 -> 4000 | H29: =F29+G29 -> 8000 | I29: 4 voos × 2 000 USD — equipa UCP (missões de supervisão)
A30: 2.2 Transportes locais (equipa de terreno) | B30: Por mês | C30: 1000 | D30: 6 | E30: 6 | F30: =C30*D30 -> 6000 | G30: =C30*E30 -> 6000 | H30: =F30+G30 -> 12000 | I30: 12m × 1 000 USD — combustível; viaturas; deslocações em Luanda
A31: SUBTOTAL 2. VIAGENS | F31: =F29+F30 -> 10000 | G31: =G29+G30 -> 10000 | H31: =H29+H30 -> 20000
A32: 3. EQUIPAMENTO E MATERIAIS
A33: 3.1 Tablets Android offline (60 unidades) | B33: Por unid. | C33: 450 | D33: 60 | E33: 0 | F33: =C33*D33 -> 27000 | G33: =C33*E33 -> 0 | H33: =F33+G33 -> 27000 | I33: 60×450 USD — SD 64GB, bateria longa duração; distribuição M5
A34: 3.2 Servidores NAS locais (Luanda) | B34: Por unid. | C34: 6000 | D34: 2 | E34: 0 | F34: =C34*D34 -> 12000 | G34: =C34*E34 -> 0 | H34: =F34+G34 -> 12000 | I34: 2×6 000 USD — gestão de conteúdos e back-up offline (redundância)
A35: 3.3 Material pedagógico impresso (6 módulos) | B35: Montante | C35: 16000 | D35: 1 | E35: 0 | F35: =C35*D35 -> 16000 | G35: =C35*E35 -> 0 | H35: =F35+G35 -> 16000 | I35: Manuais + guias facilitador + fichas avaliação — tiragem 6 000 ex.
A36: 3.4 Kits de formação (60 facilitadores) | B36: Montante | C36: 20000 | D36: 1 | E36: 0 | F36: =C36*D36 -> 20000 | G36: =C36*E36 -> 0 | H36: =F36+G36 -> 20000 | I36: 60 kits × ~333 USD — materiais; papelaria; consumíveis técnicos
A37: SUBTOTAL 3. EQUIPAMENTO E MATERIAIS | F37: =F33+F34+F35+F36 -> 75000 | G37: =G33+G34+G35+G36 -> 0 | H37: =H33+H34+H35+H36 -> 75000
A38: 4. ESCRITÓRIO DO PROJECTO
A39: 4.1 Combustível e manutenção veículo | B39: Por mês | C39: 250 | D39: 6 | E39: 6 | F39: =C39*D39 -> 1500 | G39: =C39*E39 -> 1500 | H39: =F39+G39 -> 3000 | I39: 12m × 250 USD — veículo operacional Luanda
A40: 4.2 Arrendamento de escritório (Luanda) | B40: Por mês | C40: 450 | D40: 6 | E40: 6 | F40: =C40*D40 -> 2700 | G40: =C40*E40 -> 2700 | H40: =F40+G40 -> 5400 | I40: 12m × 450 USD — espaço de trabalho equipa local
A41: 4.3 Consumíveis e material de escritório | B41: Por mês | C41: 100 | D41: 6 | E41: 6 | F41: =C41*D41 -> 600 | G41: =C41*E41 -> 600 | H41: =F41+G41 -> 1200 | I41: 12m × 100 USD — papel; tinteiro; material corrente
...

Sheet 3. Justificação
A1: JUSTIFICAÇÃO DO ORÇAMENTO DA ACÇÃO — PROJECTO ECHO ANGOLA
A3: Rubrica | B3: Descrição dos Elementos Orçamentais | C3: Justificação do Cálculo dos Custos
A4: 1. Recursos Humanos | B4: Equipa de terreno em Angola (Luanda): Coordenador Operacional, 1 Especialista Pedagógico, 1 Técnico TIC e 6 Assistentes de Campo (afetação 12 meses). Back office na sede UCP/CEPCEP em Lisboa: 3 pessoas em afetação parcial (15–30% ETI). Inclui ajudas de custo para deslocações internacionais e locais. | C4: Salários brutos (incl. encargos sociais): detalhados por pessoa na folha '1. RH por Pessoa'. Benchmark mercado angolano: técnicos 1 100–1 800 USD/mês; adm. 800–1 000 USD/mês. Sede UCP: custo efectivo da afetação parcial (15–30% × vencimento bruto). Ajudas de custo: 24d×150 + 340d×40 + 640d×10 USD = 23 600 USD. Total exacto: 200 000 USD.
A5: 2. Viagens | B5: Voos internacionais Lisboa–Luanda para missões de supervisão técnica, monitorização e avaliação pela equipa de sede UCP. Transportes locais para deslocações da equipa de terreno em Luanda (combustível, táxis, deslocações às 50 salas de formação). | C5: 4 voos internacionais × 2 000 USD = 8 000 USD (classe económica). Transportes locais: 12 meses × 1 000 USD = 12 000 USD (combustível veículo, táxis, deslocações em Luanda). Total: 20 000 USD.
A6: 3. Equipamento e Materiais | B6: 60 tablets Android robustos (conteúdos offline) distribuídos aos facilitadores; 2 servidores NAS locais em Luanda para gestão de conteúdos e back-up (redundância); material pedagógico impresso em português (6 módulos formativos, tiragem 6 000 ex.); kits de formação para os 60 facilitadores certificados. | C6: 60 tablets × 450 USD = 27 000 USD (modelos robustos: SD 64GB, bateria ≥6h, compatíveis Android 10+). 2 servidores × 6 000 USD = 12 000 USD (NAS 4TB, UPS, instalação). Material impresso: 16 000 USD (gráfica local, 6 módulos × 6 000 exemplares + guias e fichas). Kits: 20 000 USD (60 × ~333 USD). Total: 75 000 USD.
A7: 4. Escritório do Projecto | B7: Custos operacionais do escritório local em Luanda: espaço de trabalho para a equipa (arrendamento), veículo operacional (combustível e manutenção), consumíveis de escritório, comunicações (pacote dados, voz), electricidade e manutenção geral. Excluído do cálculo de custos indiretos (cat. 4 PRAG). | C7: 12m × (250+450+100+200) = 12 000 USD. Arrendamento sala comercial Luanda: 450 USD/mês (referência mercado Maianga). Veículo: 250 USD/mês (combustível + manutenção). Consumíveis: 100 USD. Comunicações: 200 USD. Total: 12 000 USD.
A8: 5. Outras Despesas e Serviços | B8: Aluguer de salas para 50 ciclos de formação em Luanda (cada ciclo = 6 sessões de 4h; 800 USD/ciclo); auditoria financeira externa intercalar (M6) e final (M12); avaliação externa independente (intermédia M7 e final M11–M12); tradução e revisão técnica de materiais; comunicação e visibilidade (site, vídeo, evento final); impressão oficial de 5 000 certificados de beneficiários e 60 de facilitadores; publicações e seminários de disseminação. | C8: Salas: 50 ciclos × 800 = 40 000. Auditoria: 2 × 4 000 = 8 000. Avaliação externa: 2 × 7 500 = 15 000. Tradução: 6 000. Serviços financeiros: 2 000. Comunicação e visibilidade: 12 000. Certificados: 4 000. Publicações e seminários: 12 000. Total: 99 000 USD.
A9: 6. Outros Custos Directos | B9: Desenvolvimento e implementação da plataforma digital offline em português (compatível com ambientes de baixa ou nula conectividade) contratada a empresa TIC angolana. Processo de certificação e acreditação oficial do programa de formação junto do MED e MINTTICS, incluindo taxas regulatórias e consultoria jurídica. | C9: Plataforma offline: 35 000 USD (contrato empresa TIC angolana; desenvolvimento M1–M3; testes beta M4; entrega M5). Certificação MED/MINTTICS: 8 000 USD (taxas regulatórias; consultoria jurídica; acreditação formal). Total: 43 000 USD.
A10: 8. Custos Indiretos | B10: Overhead e custos de estrutura institucional do CEPCEP/UCP não imputáveis directamente à acção (gestão institucional central, contabilidade, RH partilhados, infra-estrutura de sede). | C10: 7% × 437 000 USD (7.1 — custos diretos excl. escritório) = 30 590 USD. Dentro do limite máximo PRAG de 7%. Calculado automaticamente na folha '2. Orçamento PRAG'.
A11: 10.1 Reserva para Imprevistos | B11: Provisão para cobrir imprevistos cambiais (depreciação do Kwanza face ao USD), flutuações de preços locais, contingências logísticas em Luanda e situações não previstas ao longo dos 12 meses. | C11: 20 410 USD = 500 000 − 479 590 USD. Representa 4,5% de 7.2 (449 000 USD), dentro do limite PRAG de ≤5% (máximo permitido: 22 450 USD). Provisiona riscos cambiais (Kwanza/USD), flutuações de preços locais e contingências logísticas.

Sheet 4. Financiamento
A1: FONTES DE FINANCIAMENTO PREVISTAS — PROJECTO ECHO ANGOLA
A3: Fonte de Financiamento | B3: Condições / Natureza | C3: Montante (USD) | D3: % do Total
A4: A. Contribuição UE/PNUD (solicitada) | B4: Subvenção (grant) não reembolsável | C4: 400000 | D4: 0.8
A5: B. Cofinanciamento — Total | B5: Contribuições em numerário dos parceiros | C5: 100000 | D5: 0.2
A6: B.1 UCP/CEPCEP (requerente) | B6: Fundos próprios da instituição proponente | C6: 50000 | D6: 0.1
A7: B.2 Parceiros locais (FAS + UAN) | B7: Contribuições institucionais e valorização | C7: 50000 | D7: 0.1
A8: TOTAL CONTRIBUIÇÕES PREVISTAS (A + B) | B8: Equilibrado com os custos elegíveis totais | C8: 500000 | D8: 1
A10: RESUMO DOS CUSTOS
A11: C. Estimativa custos elegíveis totais (rubrica 11) | C11: 500000
A12: Contribuição UE/PNUD em % dos custos elegíveis (A/C) | C12: 0.8
A13: Equilíbrio do quadro (A+B) − C | C13: 0
